<?xml version="1.0"?>
<!-- created with Phobos 1.0.1 "Capricious Choutengan" -->
  <robot name="bittle">
<!--TODO Replace dashes with underscores in the link and joint names because
ROS doesn't like fucking dashes and these mother fuckers used dashes everywhere
and I can't just ctrl f and replace because dashes are also used as negative signs -->

    <link name="base-frame-link">
      <inertial>
        <origin xyz="0 0 0" rpy="0 0 0"/>
        <mass value="0.108"/>
        <inertia ixx="0.01562" ixy="0" ixz="-2e-05" iyy="0.00613" iyz="0" izz="0.02107"/>
      </inertial>
      <visual name="base_frame">
        <origin xyz="0 0 0" rpy="0 0 0"/>
        <geometry>
          <mesh filename="package://quad_walk/obj/base_frame.obj" scale="1.0 1.0 1.0"/>
        </geometry>
      </visual>
      <collision name="base_frame_c">
        <origin xyz="0 0 0" rpy="0 0 0"/>
        <geometry>
          <mesh filename="package://quad_walk/obj/base_frame.001.obj" scale="1.0 1.0 1.0"/>
        </geometry>
      </collision>
    </link>

    <link name="battery-link">
      <inertial>
        <origin xyz="0 0 0" rpy="0 0 0"/>
        <mass value="0.056"/>
        <inertia ixx="0.00337" ixy="0" ixz="0" iyy="0.00044" iyz="0.00031" izz="0.00361"/>
      </inertial>
      <visual name="battery">
        <origin xyz="0 0 0" rpy="0 0 0"/>
        <geometry>
          <mesh filename="package://quad_walk/obj/battery.obj" scale="1.0 1.0 1.0"/>
        </geometry>
      </visual>
      <collision name="battery_c">
        <origin xyz="0 0 0" rpy="0 0 0"/>
        <geometry>
          <mesh filename="package://quad_walk/obj/battery.001.obj" scale="1.0 1.0 1.0"/>
        </geometry>
      </collision>
    </link>

    <link name="cover-link">
      <inertial>
        <origin xyz="0 0 0" rpy="0 0 0"/>
        <mass value="0.013"/>
        <inertia ixx="0.00039" ixy="0" ixz="0" iyy="0.00057" iyz="0" izz="0.0009"/>
      </inertial>
      <visual name="cover">
        <origin xyz="0 0 0" rpy="0 0 0"/>
        <geometry>
          <mesh filename="package://quad_walk/obj/cover.obj" scale="1.0 1.0 1.0"/>
        </geometry>
      </visual>
      <collision name="cover_c">
        <origin xyz="0 0 0" rpy="0 0 0"/>
        <geometry>
          <mesh filename="package://quad_walk/obj/cover.001.obj" scale="1.0 1.0 1.0"/>
        </geometry>
      </collision>
    </link>

    <link name="imu_link">
      <inertial>
        <origin xyz="0 0 0" rpy="0 0 0"/>
        <mass value="0.001"/>
        <inertia ixx="0.001" ixy="0" ixz="0" iyy="0.001" iyz="0" izz="0.001"/>
      </inertial>
      <visual name="imu">
        <origin xyz="0 0 0" rpy="0 0 3.14159"/>
        <geometry>
          <mesh filename="package://quad_walk/obj/Cube.011.obj" scale="1.0 1.0 1.0"/>
        </geometry>
      </visual>
    </link>

    <link name="left-back-knee-link">
      <inertial>
        <origin xyz="-0.08998 0 -0.14638" rpy="0 0 0"/>
        <mass value="0.017"/>
        <inertia ixx="6e-05" ixy="-2e-05" ixz="0" iyy="0.00065" iyz="-6e-05" izz="0.00063"/>
      </inertial>
      <visual name="left_back_knee">
        <origin xyz="-0.08998 0 -0.14638" rpy="-1.5708 1.5708 0"/>
        <geometry>
          <mesh filename="package://quad_walk/obj/left_knee.001.obj" scale="1.0 1.0 1.0"/>
        </geometry>
      </visual>
      <collision name="left_back_knee_c">
        <origin xyz="-0.08998 0 -0.14638" rpy="-1.5708 1.5708 0"/>
        <geometry>
          <mesh filename="package://quad_walk/obj/left_knee.002.obj" scale="1.0 1.0 1.0"/>
        </geometry>
        <surface>
        <friction>
          <ode>
            <mu>0.85</mu>
            <mu2>0.85</mu2>
          </ode>
        </friction>
      </surface>
      </collision>
    </link>

    <link name="left-back-shoulder-link">
      <inertial>
        <origin xyz="0 -0.24575 0.04372" rpy="0 0 0"/>
        <mass value="0.006"/>
        <inertia ixx="0.00044" ixy="0" ixz="0" iyy="2e-05" iyz="0" izz="0.00044"/>
      </inertial>
      <visual name="left_back_shoulder">
        <origin xyz="0 -0.24575 0.04372" rpy="-1.5708 1.5708 0"/>
        <geometry>
          <mesh filename="package://quad_walk/obj/shoulder.001.obj" scale="1.0 1.0 1.0"/>
        </geometry>
      </visual>
      <collision name="left_back_shoulder_c">
        <origin xyz="0 -0.24575 0.04372" rpy="-1.5708 1.5708 0"/>
        <geometry>
          <mesh filename="package://quad_walk/obj/shoulder.004.obj" scale="1.0 1.0 1.0"/>
        </geometry>
        <surface>
        <friction>
          <ode>
            <mu>0.85</mu>
            <mu2>0.85</mu2>
          </ode>
        </friction>
      </surface>
      </collision>
    </link>

    <link name="left-front-knee-link">
      <inertial>
        <origin xyz="-0.09232 0 -0.14614" rpy="0 0 0"/>
        <mass value="0.017"/>
        <inertia ixx="6e-05" ixy="-2e-05" ixz="0" iyy="0.00065" iyz="-6e-05" izz="0.00063"/>
      </inertial>
      <visual name="left_front_knee">
        <origin xyz="-0.09232 0 -0.14614" rpy="-1.5708 1.5708 0"/>
        <geometry>
          <mesh filename="package://quad_walk/obj/left_knee.obj" scale="1.0 1.0 1.0"/>
        </geometry>
      </visual>
      <collision name="left_front_knee_c">
        <origin xyz="-0.09232 0 -0.14614" rpy="-1.5708 1.5708 0"/>
        <geometry>
          <mesh filename="package://quad_walk/obj/left_knee.003c.obj" scale="1.0 1.0 1.0"/>
        </geometry>
        <surface>
        <friction>
          <ode>
            <mu>0.85</mu>
            <mu2>0.85</mu2>
          </ode>
        </friction>
      </surface>
      </collision>
    </link>

    <link name="left-front-shoulder-link">
      <inertial>
        <origin xyz="0 -0.24575 0.04372" rpy="0 0 0"/>
        <mass value="0.006"/>
        <inertia ixx="0.00044" ixy="0" ixz="0" iyy="2e-05" iyz="0" izz="0.00044"/>
      </inertial>
      <visual name="left_front_shoulder">
        <origin xyz="0 -0.24575 0.04372" rpy="-1.5708 1.5708 0"/>
        <geometry>
          <mesh filename="package://quad_walk/obj/shoulder.obj" scale="1.0 1.0 1.0"/>
        </geometry>
      </visual>
      <collision name="left_front_shoulder_c">
        <origin xyz="0 -0.24575 0.04372" rpy="-1.5708 1.5708 0"/>
        <geometry>
          <mesh filename="package://quad_walk/obj/shoulder.007.obj" scale="1.0 1.0 1.0"/>
        </geometry>
        <surface>
        <friction>
          <ode>
            <mu>0.85</mu>
            <mu2>0.85</mu2>
          </ode>
        </friction>
      </surface>
      </collision>
    </link>

    <link name="mainboard_link">
      <inertial>
        <origin xyz="0 0 0" rpy="0 0 0"/>
        <mass value="0.001"/>
        <inertia ixx="0.001" ixy="0" ixz="0" iyy="0.001" iyz="0" izz="0.001"/>
      </inertial>
      <visual name="mainboard">
        <origin xyz="0 0 0" rpy="0 0 0"/>
        <geometry>
          <mesh filename="package://quad_walk/obj/Plane.obj" scale="1.0 1.0 1.0"/>
        </geometry>
      </visual>
    </link>

    <link name="right-back-knee-link">
      <inertial>
        <origin xyz="0.08426 -0.00238 -0.1382" rpy="0 0 0"/>
        <mass value="0.017"/>
        <inertia ixx="6e-05" ixy="-1e-05" ixz="0" iyy="0.00065" iyz="-3e-05" izz="0.00064"/>
      </inertial>
      <visual name="right_back_knee">
        <origin xyz="0.08426 -0.00238 -0.1382" rpy="-1.5708 -1.5708 0"/>
        <geometry>
          <mesh filename="package://quad_walk/obj/right_knee.001.obj" scale="1.0 1.0 1.0"/>
        </geometry>
      </visual>
      <collision name="right_back_knee_c">
        <origin xyz="0.08426 -0.00238 -0.1382" rpy="-1.5708 -1.5708 0"/>
        <geometry>
          <mesh filename="package://quad_walk/obj/right_knee.002c.obj" scale="1.0 1.0 1.0"/>
        </geometry>
        <surface>
        <friction>
          <ode>
            <mu>0.85</mu>
            <mu2>0.85</mu2>
          </ode>
        </friction>
      </surface>
      </collision>
    </link>

    <link name="right-back-shoulder-link">
      <inertial>
        <origin xyz="0 0.24575 0.0777" rpy="0 0 0"/>
        <mass value="0.006"/>
        <inertia ixx="0.00044" ixy="0" ixz="0" iyy="2e-05" iyz="0" izz="0.00044"/>
      </inertial>
      <visual name="right_back_shoulder">
        <origin xyz="0 0.24575 0.0777" rpy="1.5708 -1.5708 0"/>
        <geometry>
          <mesh filename="package://quad_walk/obj/shoulder.002.obj" scale="1.0 1.0 1.0"/>
        </geometry>
      </visual>
      <collision name="right_back_shoulder_c">
        <origin xyz="0 0.24575 0.0777" rpy="1.5708 -1.5708 0"/>
        <geometry>
          <mesh filename="package://quad_walk/obj/shoulder.005.obj" scale="1.0 1.0 1.0"/>
        </geometry>
        <surface>
        <friction>
          <ode>
            <mu>0.85</mu>
            <mu2>0.85</mu2>
          </ode>
        </friction>
      </surface>
      </collision>
    </link>

    <link name="right-front-knee-link">
      <inertial>
        <origin xyz="0.09497 -0.00238 -0.1382" rpy="0 0 0"/>
        <mass value="0.017"/>
        <inertia ixx="6e-05" ixy="-1e-05" ixz="0" iyy="0.00065" iyz="-3e-05" izz="0.00064"/>
      </inertial>
      <visual name="right_front_knee">
        <origin xyz="0.09497 -0.00238 -0.1382" rpy="-1.5708 -1.5708 0"/>
        <geometry>
          <mesh filename="package://quad_walk/obj/right_knee.obj" scale="1.0 1.0 1.0"/>
        </geometry>
      </visual>
      <collision name="right_front_knee_c">
        <origin xyz="0.09497 -0.00238 -0.1382" rpy="-1.5708 -1.5708 0"/>
        <geometry>
          <mesh filename="package://quad_walk/obj/right_knee.003c.obj" scale="1.0 1.0 1.0"/>
        </geometry>
        <surface>
        <friction>
          <ode>
            <mu>0.85</mu>
            <mu2>0.85</mu2>
          </ode>
        </friction>
      </surface>
      </collision>
    </link>

    <link name="right-front-shoulder-link">
      <inertial>
        <origin xyz="0 0.24575 0.0777" rpy="0 0 0"/>
        <mass value="0.006"/>
        <inertia ixx="0.00044" ixy="0" ixz="0" iyy="2e-05" iyz="0" izz="0.00044"/>
      </inertial>
      <visual name="right_front_shoulder">
        <origin xyz="0 0.24575 0.0777" rpy="1.5708 -1.5708 0"/>
        <geometry>
          <mesh filename="package://quad_walk/obj/shoulder.003.obj" scale="1.0 1.0 1.0"/>
        </geometry>
      </visual>
      <collision name="right_front_shoulder_c">
        <origin xyz="0 0.24575 0.0777" rpy="1.5708 -1.5708 0"/>
        <geometry>
          <mesh filename="package://quad_walk/obj/shoulder.006.obj" scale="1.0 1.0 1.0"/>
        </geometry>
        <surface>
        <friction>
          <ode>
            <mu>0.85</mu>
            <mu2>0.85</mu2>
          </ode>
        </friction>
      </surface>
      </collision>
    </link>

    <joint name="battery_joint" type="fixed">
      <origin xyz="0.00047 -0.00917 -0.04848" rpy="0 0 0"/>
      <parent link="base-frame-link"/>
      <child link="battery-link"/>
    </joint>

    <joint name="cover_joint" type="fixed">
      <origin xyz="0.0014 0 0.1251" rpy="0 0 0"/>
      <parent link="base-frame-link"/>
      <child link="cover-link"/>
    </joint>

    <joint name="imu_joint" type="fixed">
      <origin xyz="-0.00652 0.00827 0.00586" rpy="0 0 -3.14159"/>
      <parent link="mainboard_link"/>
      <child link="imu_link"/>
    </joint>

    <joint name="left_back_knee_joint" type="revolute">
      <origin xyz="0 -0.49172 0" rpy="0 0 0"/>
      <parent link="left-back-shoulder-link"/>
      <child link="left-back-knee-link"/>
      <axis xyz="0 0 1.0"/>
      <limit lower="-1.22173" upper="1.48353" effort="2" velocity="1.5708"/>
    </joint>

    <joint name="left_back_shoulder_joint" type="revolute">
      <origin xyz="-0.44596 -0.51923 -0.02102" rpy="1.5708 0 -1.5708"/>
      <parent link="base-frame-link"/>
      <child link="left-back-shoulder-link"/>
      <axis xyz="0 0 1.0"/>
      <limit lower="-1.5708" upper="1.22173" effort="2" velocity="1.5708"/>
    </joint>

    <joint name="left_front_knee_joint" type="revolute">
      <origin xyz="6e-05 -0.49172 0" rpy="0 0 0"/>
      <parent link="left-front-shoulder-link"/>
      <child link="left-front-knee-link"/>
      <axis xyz="0 0 1.0"/>
      <limit lower="-1.22173" upper="1.48353" effort="2" velocity="1.5708"/>
    </joint>

    <joint name="left_front_shoulder_joint" type="revolute">
      <origin xyz="-0.44596 0.52264 -0.02102" rpy="1.5708 0 -1.5708"/>
      <parent link="base-frame-link"/>
      <child link="left-front-shoulder-link"/>
      <axis xyz="0 0 1.0"/>
      <limit lower="-1.5708" upper="1.22173" effort="2" velocity="1.5708"/>
    </joint>

    <joint name="mainboard_joint" type="fixed">
      <origin xyz="0.00652 -0.00827 0.06423" rpy="0 0 0"/>
      <parent link="base-frame-link"/>
      <child link="mainboard_link"/>
    </joint>

    <joint name="right_back_knee_joint" type="revolute">
      <origin xyz="0.00015 0.49938 0.03996" rpy="0 0 3.14159"/>
      <parent link="right-back-shoulder-link"/>
      <child link="right-back-knee-link"/>
      <axis xyz="0 0 1.0"/>
      <limit lower="-1.22173" upper="1.48353" effort="2" velocity="1.5708"/>
    </joint>

    <joint name="right_back_shoulder_joint" type="revolute">
      <origin xyz="0.45149 -0.51923 -0.02102" rpy="-1.5708 0 -1.5708"/>
      <parent link="base-frame-link"/>
      <child link="right-back-shoulder-link"/>
      <axis xyz="0 0 1.0"/>
      <limit lower="-1.5708" upper="1.22173" effort="2" velocity="1.5708"/>
    </joint>

    <joint name="right_front_knee_joint" type="revolute">
      <origin xyz="6e-05 0.49938 0.03996" rpy="0 0 3.14159"/>
      <parent link="right-front-shoulder-link"/>
      <child link="right-front-knee-link"/>
      <axis xyz="0 0 1.0"/>
      <limit lower="-1.22173" upper="1.48353" effort="2" velocity="1.5708"/>
    </joint>

    <joint name="right_front_shoulder_joint" type="revolute">
      <origin xyz="0.45149 0.52264 -0.02102" rpy="-1.5708 0 -1.5708"/>
      <parent link="base-frame-link"/>
      <child link="right-front-shoulder-link"/>
      <axis xyz="0 0 1.0"/>
      <limit lower="-1.5708" upper="1.22173" effort="2" velocity="1.5708"/>
    </joint>

    <transmission name="lbk_trans" type="SimpleTransmission">
      <type>transmission_interface/SimpleTransmission</type>
      <actuator name="lbk_motor">
        <mechanicalReduction>1</mechanicalReduction>
      </actuator>
      <joint name="left_back_knee_joint">
        <hardwareInterface>hardware_interface/EffortJointInterface</hardwareInterface>
      </joint>
    </transmission>

    <transmission name="lbs_trans" type="SimpleTransmission">
      <type>transmission_interface/SimpleTransmission</type>
      <actuator name="lbs_motor">
        <mechanicalReduction>1</mechanicalReduction>
      </actuator>
      <joint name="left_back_shoulder_joint">
        <hardwareInterface>hardware_interface/EffortJointInterface</hardwareInterface>
      </joint>
    </transmission>

    <transmission name="lfk_trans" type="SimpleTransmission">
      <type>transmission_interface/SimpleTransmission</type>
      <actuator name="lfk_motor">
        <mechanicalReduction>1</mechanicalReduction>
      </actuator>
      <joint name="left_front_knee_joint">
        <hardwareInterface>hardware_interface/EffortJointInterface</hardwareInterface>
      </joint>
    </transmission>

    <transmission name="lfs_trans" type="SimpleTransmission">
      <type>transmission_interface/SimpleTransmission</type>
      <actuator name="lfs_motor">
        <mechanicalReduction>1</mechanicalReduction>
      </actuator>
      <joint name="left_front_shoulder_joint">
        <hardwareInterface>hardware_interface/EffortJointInterface</hardwareInterface>
      </joint>
    </transmission>

    <transmission name="rbk_trans" type="SimpleTransmission">
      <type>transmission_interface/SimpleTransmission</type>
      <actuator name="rbk_motor">
        <mechanicalReduction>1</mechanicalReduction>
      </actuator>
      <joint name="right_back_knee_joint">
        <hardwareInterface>hardware_interface/EffortJointInterface</hardwareInterface>
      </joint>
    </transmission>

    <transmission name="rbs_trans" type="SimpleTransmission">
      <type>transmission_interface/SimpleTransmission</type>
      <actuator name="rbs_motor">
        <mechanicalReduction>1</mechanicalReduction>
      </actuator>
      <joint name="right_back_shoulder_joint">
        <hardwareInterface>hardware_interface/EffortJointInterface</hardwareInterface>
      </joint>
    </transmission>

    <transmission name="rfk_trans" type="SimpleTransmission">
      <type>transmission_interface/SimpleTransmission</type>
      <actuator name="rfk_motor">
        <mechanicalReduction>1</mechanicalReduction>
      </actuator>
      <joint name="right_front_knee_joint">
        <hardwareInterface>hardware_interface/EffortJointInterface</hardwareInterface>
      </joint>
    </transmission>

    <transmission name="rfs_trans" type="SimpleTransmission">
      <type>transmission_interface/SimpleTransmission</type>
      <actuator name="rfs_motor">
        <mechanicalReduction>1</mechanicalReduction>
      </actuator>
      <joint name="right_front_shoulder_joint">
        <hardwareInterface>hardware_interface/EffortJointInterface</hardwareInterface>
      </joint>
    </transmission>

    <gazebo>
      <plugin name="gazebo_ros_control" filename="libgazebo_ros_control.so">
        <robotNamespace></robotNamespace>
      </plugin>
    </gazebo>

  </robot>
